<?xml version="1.0" ?>
<robot name="40DegRotorAssembly" xmlns:xacro="http://www.ros.org/wiki/xacro">

<xacro:include filename="$(find 40DegRotorAssembly_description)/urdf/materials.xacro" />
<xacro:include filename="$(find 40DegRotorAssembly_description)/urdf/40DegRotorAssembly.trans" />
<xacro:include filename="$(find 40DegRotorAssembly_description)/urdf/40DegRotorAssembly.gazebo" />
<link name="base_link">
  <inertial>
    <origin xyz="7.735065992124888e-14 1.7881390223770156e-10 -0.013027047773476432" rpy="0 0 0"/>
    <mass value="0.06630753960006285"/>
    <inertia ixx="1e-05" iyy="1e-05" izz="1.8e-05" ixy="-0.0" iyz="-0.0" ixz="0.0"/>
  </inertial>
  <visual>
    <origin xyz="0 0 0" rpy="0 0 0"/>
    <geometry>
      <mesh filename="package://40DegRotorAssembly_description/meshes/base_link.stl" scale="0.001 0.001 0.001"/>
    </geometry>
    <material name="silver"/>
  </visual>
  <collision>
    <origin xyz="0 0 0" rpy="0 0 0"/>
    <geometry>
      <mesh filename="package://40DegRotorAssembly_description/meshes/base_link.stl" scale="0.001 0.001 0.001"/>
    </geometry>
  </collision>
</link>

<link name="hub_1">
  <inertial>
    <origin xyz="6.408040703700102e-08 4.521367438227419e-06 0.02115033137979168" rpy="0 0 0"/>
    <mass value="0.045875486442851464"/>
    <inertia ixx="1.6e-05" iyy="1.5e-05" izz="2e-05" ixy="-0.0" iyz="-0.0" ixz="0.0"/>
  </inertial>
  <visual>
    <origin xyz="0.0 -0.0 0.025" rpy="0 0 0"/>
    <geometry>
      <mesh filename="package://40DegRotorAssembly_description/meshes/hub_1.stl" scale="0.001 0.001 0.001"/>
    </geometry>
    <material name="silver"/>
  </visual>
  <collision>
    <origin xyz="0.0 -0.0 0.025" rpy="0 0 0"/>
    <geometry>
      <mesh filename="package://40DegRotorAssembly_description/meshes/hub_1.stl" scale="0.001 0.001 0.001"/>
    </geometry>
  </collision>
</link>

<link name="teetering_hub_1">
  <inertial>
    <origin xyz="2.3047318532386023e-16 -2.0023549347411018e-10 -2.5549701243576806e-13" rpy="0 0 0"/>
    <mass value="0.006675322687084224"/>
    <inertia ixx="0.0" iyy="1e-06" izz="1e-06" ixy="0.0" iyz="-0.0" ixz="-0.0"/>
  </inertial>
  <visual>
    <origin xyz="-0.0 0.0 -0.028" rpy="0 0 0"/>
    <geometry>
      <mesh filename="package://40DegRotorAssembly_description/meshes/teetering_hub_1.stl" scale="0.001 0.001 0.001"/>
    </geometry>
    <material name="silver"/>
  </visual>
  <collision>
    <origin xyz="-0.0 0.0 -0.028" rpy="0 0 0"/>
    <geometry>
      <mesh filename="package://40DegRotorAssembly_description/meshes/teetering_hub_1.stl" scale="0.001 0.001 0.001"/>
    </geometry>
  </collision>
</link>

<link name="side_hub_positive_1">
  <inertial>
    <origin xyz="-0.0574472904647423 0.000772192735747795 0.0005609882602239658" rpy="0 0 0"/>
    <mass value="0.009175981053557224"/>
    <inertia ixx="0.0" iyy="2.6e-05" izz="2.6e-05" ixy="0.0" iyz="0.0" ixz="-0.0"/>
  </inertial>
  <visual>
    <origin xyz="0.015 -0.0 -0.028" rpy="0 0 0"/>
    <geometry>
      <mesh filename="package://40DegRotorAssembly_description/meshes/side_hub_positive_1.stl" scale="0.001 0.001 0.001"/>
    </geometry>
    <material name="silver"/>
  </visual>
  <collision>
    <origin xyz="0.015 -0.0 -0.028" rpy="0 0 0"/>
    <geometry>
      <mesh filename="package://40DegRotorAssembly_description/meshes/side_hub_positive_1.stl" scale="0.001 0.001 0.001"/>
    </geometry>
  </collision>
</link>

<link name="side_hub_negative_1">
  <inertial>
    <origin xyz="0.05744729046094746 -0.0007721864572502097 -0.0009849110217392404" rpy="0 0 0"/>
    <mass value="0.009175981053061298"/>
    <inertia ixx="0.0" iyy="2.6e-05" izz="2.6e-05" ixy="0.0" iyz="-0.0" ixz="-0.0"/>
  </inertial>
  <visual>
    <origin xyz="-0.015 -0.0 -0.028" rpy="0 0 0"/>
    <geometry>
      <mesh filename="package://40DegRotorAssembly_description/meshes/side_hub_negative_1.stl" scale="0.001 0.001 0.001"/>
    </geometry>
    <material name="silver"/>
  </visual>
  <collision>
    <origin xyz="-0.015 -0.0 -0.028" rpy="0 0 0"/>
    <geometry>
      <mesh filename="package://40DegRotorAssembly_description/meshes/side_hub_negative_1.stl" scale="0.001 0.001 0.001"/>
    </geometry>
  </collision>
</link>

<joint name="Revolute 1" type="continuous">
  <origin xyz="0.0 0.0 -0.025" rpy="0 0 0"/>
  <parent link="base_link"/>
  <child link="hub_1"/>
  <axis xyz="0.0 -0.0 1.0"/>
</joint>

<joint name="Revolute 2" type="continuous">
  <origin xyz="0.0 -0.0 0.053" rpy="0 0 0"/>
  <parent link="hub_1"/>
  <child link="teetering_hub_1"/>
  <axis xyz="-0.0 -1.0 -0.0"/>
</joint>

<joint name="Revolute 6" type="continuous">
  <origin xyz="-0.015 0.0 0.0" rpy="0 0 0"/>
  <parent link="teetering_hub_1"/>
  <child link="side_hub_positive_1"/>
  <axis xyz="-0.707107 0.0 -0.707107"/>
</joint>

<joint name="Revolute 7" type="continuous">
  <origin xyz="0.015 0.0 0.0" rpy="0 0 0"/>
  <parent link="teetering_hub_1"/>
  <child link="side_hub_negative_1"/>
  <axis xyz="-0.707107 0.0 -0.707107"/>
</joint>

</robot>
