<?xml version="1.0" ?>
<robot name="40DegRotorAssembly" xmlns:xacro="http://www.ros.org/wiki/xacro">

<xacro:include filename="$(find 40DegRotorAssembly_description)/urdf/materials.xacro" />
<xacro:include filename="$(find 40DegRotorAssembly_description)/urdf/40DegRotorAssembly.trans" />
<xacro:include filename="$(find 40DegRotorAssembly_description)/urdf/40DegRotorAssembly.gazebo" />
<link name="base_link">
  <inertial>
    <origin xyz="7.735065992124888e-14 1.7881390223770156e-10 -0.013027047773476432" rpy="0 0 0"/>
    <mass value="0.04838658295139721"/>
    <inertia ixx="7e-06" iyy="7e-06" izz="1.3e-05" ixy="-0.0" iyz="-0.0" ixz="0.0"/>
  </inertial>
  <visual>
    <origin xyz="0 0 0" rpy="0 0 0"/>
    <geometry>
      <mesh filename="package://40DegRotorAssembly_description/meshes/base_link.stl" scale="0.001 0.001 0.001"/>
    </geometry>
    <material name="silver"/>
  </visual>
  <collision>
    <origin xyz="0 0 0" rpy="0 0 0"/>
    <geometry>
      <mesh filename="package://40DegRotorAssembly_description/meshes/base_link.stl" scale="0.001 0.001 0.001"/>
    </geometry>
  </collision>
</link>

<link name="hub_1">
  <inertial>
    <origin xyz="6.957655821438106e-08 2.323109289112266e-06 0.018963003712836154" rpy="0 0 0"/>
    <mass value="0.06559900346349373"/>
    <inertia ixx="2.1e-05" iyy="2e-05" izz="3.2e-05" ixy="-0.0" iyz="-0.0" ixz="0.0"/>
  </inertial>
  <visual>
    <origin xyz="0.0 -0.0 0.025" rpy="0 0 0"/>
    <geometry>
      <mesh filename="package://40DegRotorAssembly_description/meshes/hub_1.stl" scale="0.001 0.001 0.001"/>
    </geometry>
    <material name="silver"/>
  </visual>
  <collision>
    <origin xyz="0.0 -0.0 0.025" rpy="0 0 0"/>
    <geometry>
      <mesh filename="package://40DegRotorAssembly_description/meshes/hub_1.stl" scale="0.001 0.001 0.001"/>
    </geometry>
  </collision>
</link>

<link name="teetering_hub_1">
  <inertial>
    <origin xyz="3.359834451415809e-16 -2.0025242890718843e-10 -1.923287917815486e-13" rpy="0 0 0"/>
    <mass value="0.004049823722403734"/>
    <inertia ixx="0.0" iyy="0.0" izz="0.0" ixy="0.0" iyz="-0.0" ixz="-0.0"/>
  </inertial>
  <visual>
    <origin xyz="-0.0 0.0 -0.028" rpy="0 0 0"/>
    <geometry>
      <mesh filename="package://40DegRotorAssembly_description/meshes/teetering_hub_1.stl" scale="0.001 0.001 0.001"/>
    </geometry>
    <material name="silver"/>
  </visual>
  <collision>
    <origin xyz="-0.0 0.0 -0.028" rpy="0 0 0"/>
    <geometry>
      <mesh filename="package://40DegRotorAssembly_description/meshes/teetering_hub_1.stl" scale="0.001 0.001 0.001"/>
    </geometry>
  </collision>
</link>

<link name="side_hub_positive_1">
  <inertial>
    <origin xyz="-0.06261744333947866 0.0008458341989499758 0.00040287234623248916" rpy="0 0 0"/>
    <mass value="0.007284417638717653"/>
    <inertia ixx="0.0" iyy="2.1e-05" izz="2.1e-05" ixy="0.0" iyz="0.0" ixz="-0.0"/>
  </inertial>
  <visual>
    <origin xyz="0.015 -0.0 -0.028" rpy="0 0 0"/>
    <geometry>
      <mesh filename="package://40DegRotorAssembly_description/meshes/side_hub_positive_1.stl" scale="0.001 0.001 0.001"/>
    </geometry>
    <material name="silver"/>
  </visual>
  <collision>
    <origin xyz="0.015 -0.0 -0.028" rpy="0 0 0"/>
    <geometry>
      <mesh filename="package://40DegRotorAssembly_description/meshes/side_hub_positive_1.stl" scale="0.001 0.001 0.001"/>
    </geometry>
  </collision>
</link>

<link name="side_hub_negative_1">
  <inertial>
    <origin xyz="0.06261744333825596 -0.0008458284995726833 -0.00086722353949013" rpy="0 0 0"/>
    <mass value="0.007284417637995881"/>
    <inertia ixx="0.0" iyy="2.1e-05" izz="2.1e-05" ixy="0.0" iyz="-0.0" ixz="-0.0"/>
  </inertial>
  <visual>
    <origin xyz="-0.015 -0.0 -0.028" rpy="0 0 0"/>
    <geometry>
      <mesh filename="package://40DegRotorAssembly_description/meshes/side_hub_negative_1.stl" scale="0.001 0.001 0.001"/>
    </geometry>
    <material name="silver"/>
  </visual>
  <collision>
    <origin xyz="-0.015 -0.0 -0.028" rpy="0 0 0"/>
    <geometry>
      <mesh filename="package://40DegRotorAssembly_description/meshes/side_hub_negative_1.stl" scale="0.001 0.001 0.001"/>
    </geometry>
  </collision>
</link>

<joint name="Revolute 1" type="continuous">
  <origin xyz="0.0 0.0 -0.025" rpy="0 0 0"/>
  <parent link="base_link"/>
  <child link="hub_1"/>
  <axis xyz="0.0 -0.0 1.0"/>
</joint>

<joint name="Revolute 2" type="continuous">
  <origin xyz="0.0 -0.0 0.053" rpy="0 0 0"/>
  <parent link="hub_1"/>
  <child link="teetering_hub_1"/>
  <axis xyz="-0.0 -1.0 -0.0"/>
</joint>

<joint name="Revolute 6" type="continuous">
  <origin xyz="-0.015 0.0 0.0" rpy="0 0 0"/>
  <parent link="teetering_hub_1"/>
  <child link="side_hub_positive_1"/>
  <axis xyz="-0.707107 0.0 -0.707107"/>
</joint>

<joint name="Revolute 7" type="continuous">
  <origin xyz="0.015 0.0 0.0" rpy="0 0 0"/>
  <parent link="teetering_hub_1"/>
  <child link="side_hub_negative_1"/>
  <axis xyz="-0.707107 0.0 -0.707107"/>
</joint>

</robot>
