<?xml version="1.0" ?>
<!-- =================================================================================== -->
<!-- |    This document was autogenerated by xacro from 40DegRotorAssembly.xacro       | -->
<!-- |    EDITING THIS FILE BY HAND IS NOT RECOMMENDED                                 | -->
<!-- =================================================================================== -->
<robot name="40DegRotorAssembly">
  <material name="silver">
    <color rgba="0.40 0.40 0.40 1.000"/>
  </material>
  <material name="orange">
      <color rgba="1.0 0.423 0.039 1.0"/>
  </material>
  <material name="blue">
    <color rgba="0.0 0.0 0.8 1.0"/>
  </material>
  <material name="black">
    <color rgba="0.0 0.0 0.0 1.000"/>
  </material>
  <material name="red">
    <color rgba="0.900 0.05 0.05 1.000"/>
  </material>
  <transmission name="Revolute 1_tran">
    <type>transmission_interface/SimpleTransmission</type>
    <joint name="Revolute 1">
      <hardwareInterface>hardware_interface/EffortJointInterface</hardwareInterface>
    </joint>
    <actuator name="Revolute 1_actr">
      <hardwareInterface>hardware_interface/EffortJointInterface</hardwareInterface>
      <mechanicalReduction>1</mechanicalReduction>
    </actuator>
  </transmission>
  <transmission name="Revolute 2_tran">
    <type>transmission_interface/SimpleTransmission</type>
    <joint name="Revolute 2">
      <hardwareInterface>hardware_interface/EffortJointInterface</hardwareInterface>
    </joint>
    <actuator name="Revolute 2_actr">
      <hardwareInterface>hardware_interface/EffortJointInterface</hardwareInterface>
      <mechanicalReduction>1</mechanicalReduction>
    </actuator>
  </transmission>
  <transmission name="Revolute 6_tran">
    <type>transmission_interface/SimpleTransmission</type>
    <joint name="Revolute 6">
      <hardwareInterface>hardware_interface/EffortJointInterface</hardwareInterface>
    </joint>
    <actuator name="Revolute 6_actr">
      <hardwareInterface>hardware_interface/EffortJointInterface</hardwareInterface>
      <mechanicalReduction>1</mechanicalReduction>
    </actuator>
  </transmission>
  <transmission name="Revolute 7_tran">
    <type>transmission_interface/SimpleTransmission</type>
    <joint name="Revolute 7">
      <hardwareInterface>hardware_interface/EffortJointInterface</hardwareInterface>
    </joint>
    <actuator name="Revolute 7_actr">
      <hardwareInterface>hardware_interface/EffortJointInterface</hardwareInterface>
      <mechanicalReduction>1</mechanicalReduction>
    </actuator>
  </transmission>
  <gazebo>
    <plugin filename="libgazebo_ros_control.so" name="control"/>
  </gazebo>
  <gazebo reference="base_link">
    <material>Gazebo/Silver</material>
    <mu1>0.2</mu1>
    <mu2>0.2</mu2>
    <selfCollide>true</selfCollide>
    <gravity>true</gravity>
  </gazebo>
  <gazebo reference="hub_1">
    <material>Gazebo/Silver</material>
    <mu1>0.2</mu1>
    <mu2>0.2</mu2>
    <selfCollide>true</selfCollide>
  </gazebo>
  <gazebo reference="teetering_hub_1">
    <material>Gazebo/Silver</material>
    <mu1>0.2</mu1>
    <mu2>0.2</mu2>
    <selfCollide>true</selfCollide>
  </gazebo>
  <gazebo reference="side_hub_positive_1">
    <material>Gazebo/Silver</material>
    <mu1>0.2</mu1>
    <mu2>0.2</mu2>
    <selfCollide>true</selfCollide>
  </gazebo>
  <gazebo reference="side_hub_negative_1">
    <material>Gazebo/Silver</material>
    <mu1>0.2</mu1>
    <mu2>0.2</mu2>
    <selfCollide>true</selfCollide>
  </gazebo>
  <link name="base_link">
    <inertial>
      <origin rpy="0 0 0" xyz="7.735065992124888e-14 1.7881390223770156e-10 -0.013027047773476432"/>
      <mass value="0.06630753960006285"/>
      <inertia ixx="1e-05" ixy="-0.0" ixz="0.0" iyy="1e-05" iyz="-0.0" izz="1.8e-05"/>
    </inertial>
    <visual>
      <origin rpy="0 0 0" xyz="0 0 0"/>
      <geometry>
        <mesh filename="package://40DegRotorAssembly_description/meshes/base_link.stl" scale="0.001 0.001 0.001"/>
      </geometry>
      <material name="red"/>
    </visual>
    <collision>
      <origin rpy="0 0 0" xyz="0 0 0"/>
      <geometry>
        <mesh filename="package://40DegRotorAssembly_description/meshes/base_link.stl" scale="0.001 0.001 0.001"/>
      </geometry>
    </collision>
  </link>
  <link name="hub_1">
    <inertial>
      <origin rpy="0 0 0" xyz="6.408040703700102e-08 4.521367438227419e-06 0.02115033137979168"/>
      <mass value="0.045875486442851464"/>
      <inertia ixx="1.6e-05" ixy="-0.0" ixz="0.0" iyy="1.5e-05" iyz="-0.0" izz="2e-05"/>
    </inertial>
    <visual>
      <origin rpy="0 0 0" xyz="0.0 -0.0 0.025"/>
      <geometry>
        <mesh filename="package://40DegRotorAssembly_description/meshes/hub_1.stl" scale="0.001 0.001 0.001"/>
      </geometry>
      <material name="black"/>
    </visual>
    <collision>
      <origin rpy="0 0 0" xyz="0.0 -0.0 0.025"/>
      <geometry>
        <mesh filename="package://40DegRotorAssembly_description/meshes/hub_1.stl" scale="0.001 0.001 0.001"/>
      </geometry>
    </collision>
  </link>
  <link name="teetering_hub_1">
    <inertial>
      <origin rpy="0 0 0" xyz="2.3047318532386023e-16 -2.0023549347411018e-10 -2.5549701243576806e-13"/>
      <mass value="0.006675322687084224"/>
      <inertia ixx="0.0" ixy="0.0" ixz="-0.0" iyy="1e-06" iyz="-0.0" izz="1e-06"/>
    </inertial>
    <visual>
      <origin rpy="0 0 0" xyz="-0.0 0.0 -0.028"/>
      <geometry>
        <mesh filename="package://40DegRotorAssembly_description/meshes/teetering_hub_1.stl" scale="0.001 0.001 0.001"/>
      </geometry>
      <material name="orange"/>
    </visual>
    <collision>
      <origin rpy="0 0 0" xyz="-0.0 0.0 -0.028"/>
      <geometry>
        <mesh filename="package://40DegRotorAssembly_description/meshes/teetering_hub_1.stl" scale="0.001 0.001 0.001"/>
      </geometry>
    </collision>
  </link>
  <link name="side_hub_positive_1">
    <inertial>
      <origin rpy="0 0 0" xyz="-0.0574472904647423 0.000772192735747795 0.0005609882602239658"/>
      <mass value="0.009175981053557224"/>
      <inertia ixx="0.0" ixy="0.0" ixz="-0.0" iyy="2.6e-05" iyz="0.0" izz="2.6e-05"/>
    </inertial>
    <visual>
      <origin rpy="0 0 0" xyz="0.015 -0.0 -0.028"/>
      <geometry>
        <mesh filename="package://40DegRotorAssembly_description/meshes/side_hub_positive_1.stl" scale="0.001 0.001 0.001"/>
      </geometry>
      <material name="silver"/>
    </visual>
    <collision>
      <origin rpy="0 0 0" xyz="0.015 -0.0 -0.028"/>
      <geometry>
        <mesh filename="package://40DegRotorAssembly_description/meshes/side_hub_positive_1.stl" scale="0.001 0.001 0.001"/>
      </geometry>
    </collision>
  </link>
  <link name="side_hub_negative_1">
    <inertial>
      <origin rpy="0 0 0" xyz="0.05744729046094746 -0.0007721864572502097 -0.0009849110217392404"/>
      <mass value="0.009175981053061298"/>
      <inertia ixx="0.0" ixy="0.0" ixz="-0.0" iyy="2.6e-05" iyz="-0.0" izz="2.6e-05"/>
    </inertial>
    <visual>
      <origin rpy="0 0 0" xyz="-0.015 -0.0 -0.028"/>
      <geometry>
        <mesh filename="package://40DegRotorAssembly_description/meshes/side_hub_negative_1.stl" scale="0.001 0.001 0.001"/>
      </geometry>
      <material name="silver"/>
    </visual>
    <collision>
      <origin rpy="0 0 0" xyz="-0.015 -0.0 -0.028"/>
      <geometry>
        <mesh filename="package://40DegRotorAssembly_description/meshes/side_hub_negative_1.stl" scale="0.001 0.001 0.001"/>
      </geometry>
    </collision>
  </link>
  <joint name="Revolute 1" type="continuous">
    <origin rpy="0 0 0" xyz="0.0 0.0 -0.025"/>
    <parent link="base_link"/>
    <child link="hub_1"/>
    <axis xyz="0.0 -0.0 1.0"/>
  </joint>
  <joint name="Revolute 2" type="continuous">
    <origin rpy="0 0 0" xyz="0.0 -0.0 0.053"/>
    <parent link="hub_1"/>
    <child link="teetering_hub_1"/>
    <axis xyz="-0.0 -1.0 -0.0"/>
  </joint>
  <joint name="Revolute 6" type="continuous">
    <origin rpy="0 0 0" xyz="-0.015 0.0 0.0"/>
    <parent link="teetering_hub_1"/>
    <child link="side_hub_positive_1"/>
    <axis xyz="-0.707107 0.0 -0.707107"/>
  </joint>
  <joint name="Revolute 7" type="continuous">
    <origin rpy="0 0 0" xyz="0.015 0.0 0.0"/>
    <parent link="teetering_hub_1"/>
    <child link="side_hub_negative_1"/>
    <axis xyz="-0.707107 0.0 -0.707107"/>
  </joint>
</robot>

