<?xml version="1.0" ?>
<!-- =================================================================================== -->
<!-- |    This document was autogenerated by xacro from 40DegRotorAssembly.xacro       | -->
<!-- |    EDITING THIS FILE BY HAND IS NOT RECOMMENDED                                 | -->
<!-- =================================================================================== -->
<robot name="40DegRotorAssembly">
  <material name="silver">
    <color rgba="0.40 0.40 0.40 1.000"/>
  </material>
  <material name="orange">
      <color rgba="1.0 0.423 0.039 1.0"/>
  </material>
  <material name="blue">
    <color rgba="0.0 0.0 0.8 1.0"/>
  </material>
  <material name="black">
    <color rgba="0.0 0.0 0.0 1.000"/>
  </material>
  <material name="red">
    <color rgba="0.900 0.05 0.05 1.000"/>
  </material>
  <transmission name="Revolute 1_tran">
    <type>transmission_interface/SimpleTransmission</type>
    <joint name="Revolute 1">
      <hardwareInterface>hardware_interface/EffortJointInterface</hardwareInterface>
    </joint>
    <actuator name="Revolute 1_actr">
      <hardwareInterface>hardware_interface/EffortJointInterface</hardwareInterface>
      <mechanicalReduction>1</mechanicalReduction>
    </actuator>
  </transmission>
  <transmission name="Revolute 2_tran">
    <type>transmission_interface/SimpleTransmission</type>
    <joint name="Revolute 2">
      <hardwareInterface>hardware_interface/EffortJointInterface</hardwareInterface>
    </joint>
    <actuator name="Revolute 2_actr">
      <hardwareInterface>hardware_interface/EffortJointInterface</hardwareInterface>
      <mechanicalReduction>1</mechanicalReduction>
    </actuator>
  </transmission>
  <transmission name="Revolute 6_tran">
    <type>transmission_interface/SimpleTransmission</type>
    <joint name="Revolute 6">
      <hardwareInterface>hardware_interface/EffortJointInterface</hardwareInterface>
    </joint>
    <actuator name="Revolute 6_actr">
      <hardwareInterface>hardware_interface/EffortJointInterface</hardwareInterface>
      <mechanicalReduction>1</mechanicalReduction>
    </actuator>
  </transmission>
  <transmission name="Revolute 7_tran">
    <type>transmission_interface/SimpleTransmission</type>
    <joint name="Revolute 7">
      <hardwareInterface>hardware_interface/EffortJointInterface</hardwareInterface>
    </joint>
    <actuator name="Revolute 7_actr">
      <hardwareInterface>hardware_interface/EffortJointInterface</hardwareInterface>
      <mechanicalReduction>1</mechanicalReduction>
    </actuator>
  </transmission>
  <gazebo>
    <plugin filename="libgazebo_ros_control.so" name="control"/>
  </gazebo>
  <gazebo reference="base_link">
    <material>Gazebo/Silver</material>
    <mu1>0.2</mu1>
    <mu2>0.2</mu2>
    <selfCollide>true</selfCollide>
    <gravity>true</gravity>
  </gazebo>
  <gazebo reference="hub_1">
    <material>Gazebo/Silver</material>
    <mu1>0.2</mu1>
    <mu2>0.2</mu2>
    <selfCollide>true</selfCollide>
  </gazebo>
  <gazebo reference="teetering_hub_1">
    <material>Gazebo/Silver</material>
    <mu1>0.2</mu1>
    <mu2>0.2</mu2>
    <selfCollide>true</selfCollide>
  </gazebo>
  <gazebo reference="side_hub_positive_1">
    <material>Gazebo/Silver</material>
    <mu1>0.2</mu1>
    <mu2>0.2</mu2>
    <selfCollide>true</selfCollide>
  </gazebo>
  <gazebo reference="side_hub_negative_1">
    <material>Gazebo/Silver</material>
    <mu1>0.2</mu1>
    <mu2>0.2</mu2>
    <selfCollide>true</selfCollide>
  </gazebo>
  <link name="base_link">
    <inertial>
      <origin rpy="0 0 0" xyz="7.735065992124888e-14 1.7881390223770156e-10 -0.013027047773476432"/>
      <mass value="0.04838658295139721"/>
      <inertia ixx="7e-06" ixy="-0.0" ixz="0.0" iyy="7e-06" iyz="-0.0" izz="1.3e-05"/>
    </inertial>
    <visual>
      <origin rpy="0 0 0" xyz="0 0 0"/>
      <geometry>
        <mesh filename="package://40DegRotorAssembly_description/meshes/base_link.stl" scale="0.001 0.001 0.001"/>
      </geometry>
      <material name="red"/>
    </visual>
    <collision>
      <origin rpy="0 0 0" xyz="0 0 0"/>
      <geometry>
        <mesh filename="package://40DegRotorAssembly_description/meshes/base_link.stl" scale="0.001 0.001 0.001"/>
      </geometry>
    </collision>
  </link>
  <link name="hub_1">
    <inertial>
      <origin rpy="0 0 0" xyz="6.957655821438106e-08 2.323109289112266e-06 0.018963003712836154"/>
      <mass value="0.06559900346349373"/>
      <inertia ixx="2.1e-05" ixy="-0.0" ixz="0.0" iyy="2e-05" iyz="-0.0" izz="3.2e-05"/>
    </inertial>
    <visual>
      <origin rpy="0 0 0" xyz="0.0 -0.0 0.025"/>
      <geometry>
        <mesh filename="package://40DegRotorAssembly_description/meshes/hub_1.stl" scale="0.001 0.001 0.001"/>
      </geometry>
      <material name="black"/>
    </visual>
    <collision>
      <origin rpy="0 0 0" xyz="0.0 -0.0 0.025"/>
      <geometry>
        <mesh filename="package://40DegRotorAssembly_description/meshes/hub_1.stl" scale="0.001 0.001 0.001"/>
      </geometry>
    </collision>
  </link>
  <link name="teetering_hub_1">
    <inertial>
      <origin rpy="0 0 0" xyz="3.359834451415809e-16 -2.0025242890718843e-10 -1.923287917815486e-13"/>
      <mass value="0.004049823722403734"/>
      <inertia ixx="0.0" ixy="0.0" ixz="-0.0" iyy="0.0" iyz="-0.0" izz="0.0"/>
    </inertial>
    <visual>
      <origin rpy="0 0 0" xyz="-0.0 0.0 -0.028"/>
      <geometry>
        <mesh filename="package://40DegRotorAssembly_description/meshes/teetering_hub_1.stl" scale="0.001 0.001 0.001"/>
      </geometry>
      <material name="orange"/>
    </visual>
    <collision>
      <origin rpy="0 0 0" xyz="-0.0 0.0 -0.028"/>
      <geometry>
        <mesh filename="package://40DegRotorAssembly_description/meshes/teetering_hub_1.stl" scale="0.001 0.001 0.001"/>
      </geometry>
    </collision>
  </link>
  <link name="side_hub_positive_1">
    <inertial>
      <origin rpy="0 0 0" xyz="-0.06261744333947866 0.0008458341989499758 0.00040287234623248916"/>
      <mass value="0.007284417638717653"/>
      <inertia ixx="0.0" ixy="0.0" ixz="-0.0" iyy="2.1e-05" iyz="0.0" izz="2.1e-05"/>
    </inertial>
    <visual>
      <origin rpy="0 0 0" xyz="0.015 -0.0 -0.028"/>
      <geometry>
        <mesh filename="package://40DegRotorAssembly_description/meshes/side_hub_positive_1.stl" scale="0.001 0.001 0.001"/>
      </geometry>
      <material name="silver"/>
    </visual>
    <collision>
      <origin rpy="0 0 0" xyz="0.015 -0.0 -0.028"/>
      <geometry>
        <mesh filename="package://40DegRotorAssembly_description/meshes/side_hub_positive_1.stl" scale="0.001 0.001 0.001"/>
      </geometry>
    </collision>
  </link>
  <link name="side_hub_negative_1">
    <inertial>
      <origin rpy="0 0 0" xyz="0.06261744333825596 -0.0008458284995726833 -0.00086722353949013"/>
      <mass value="0.007284417637995881"/>
      <inertia ixx="0.0" ixy="0.0" ixz="-0.0" iyy="2.1e-05" iyz="-0.0" izz="2.1e-05"/>
    </inertial>
    <visual>
      <origin rpy="0 0 0" xyz="-0.015 -0.0 -0.028"/>
      <geometry>
        <mesh filename="package://40DegRotorAssembly_description/meshes/side_hub_negative_1.stl" scale="0.001 0.001 0.001"/>
      </geometry>
      <material name="silver"/>
    </visual>
    <collision>
      <origin rpy="0 0 0" xyz="-0.015 -0.0 -0.028"/>
      <geometry>
        <mesh filename="package://40DegRotorAssembly_description/meshes/side_hub_negative_1.stl" scale="0.001 0.001 0.001"/>
      </geometry>
    </collision>
  </link>
  <joint name="Revolute 1" type="continuous">
    <origin rpy="0 0 0" xyz="0.0 0.0 -0.025"/>
    <parent link="base_link"/>
    <child link="hub_1"/>
    <axis xyz="0.0 -0.0 1.0"/>
  </joint>
  <joint name="Revolute 2" type="continuous">
    <origin rpy="0 0 0" xyz="0.0 -0.0 0.053"/>
    <parent link="hub_1"/>
    <child link="teetering_hub_1"/>
    <axis xyz="-0.0 -1.0 -0.0"/>
  </joint>
  <joint name="Revolute 6" type="continuous">
    <origin rpy="0 0 0" xyz="-0.015 0.0 0.0"/>
    <parent link="teetering_hub_1"/>
    <child link="side_hub_positive_1"/>
    <axis xyz="-0.707107 0.0 -0.707107"/>
  </joint>
  <joint name="Revolute 7" type="continuous">
    <origin rpy="0 0 0" xyz="0.015 0.0 0.0"/>
    <parent link="teetering_hub_1"/>
    <child link="side_hub_negative_1"/>
    <axis xyz="-0.707107 0.0 -0.707107"/>
  </joint>
</robot>

