<?xml version="1.0" ?>
<robot name="RotorAssemblyFullURDF" xmlns:xacro="http://www.ros.org/wiki/xacro">

<xacro:include filename="$(find RotorAssemblyFullURDF_description)/urdf/materials.xacro" />
<xacro:include filename="$(find RotorAssemblyFullURDF_description)/urdf/RotorAssemblyFullURDF.trans" />
<xacro:include filename="$(find RotorAssemblyFullURDF_description)/urdf/RotorAssemblyFullURDF.gazebo" />
<link name="base_link">
  <inertial>
    <origin xyz="7.738042425137721e-14 1.7881392864610074e-10 -0.013027047773476477" rpy="0 0 0"/>
    <mass value="0.04838658295139719"/>
    <inertia ixx="7e-06" iyy="7e-06" izz="1.3e-05" ixy="0.0" iyz="0.0" ixz="0.0"/>
  </inertial>
  <visual>
    <origin xyz="0 0 0" rpy="0 0 0"/>
    <geometry>
      <mesh filename="package://RotorAssemblyFullURDF_description/meshes/base_link.stl" scale="0.001 0.001 0.001"/>
    </geometry>
    <material name="silver"/>
  </visual>
  <collision>
    <origin xyz="0 0 0" rpy="0 0 0"/>
    <geometry>
      <mesh filename="package://RotorAssemblyFullURDF_description/meshes/base_link.stl" scale="0.001 0.001 0.001"/>
    </geometry>
  </collision>
</link>

<link name="hub_1">
  <inertial>
    <origin xyz="5.134385663919432e-06 5.324199036162284e-08 0.02045097842795695" rpy="0 0 0"/>
    <mass value="0.025233763410004266"/>
    <inertia ixx="7e-06" iyy="8e-06" izz="1.1e-05" ixy="-0.0" iyz="0.0" ixz="-0.0"/>
  </inertial>
  <visual>
    <origin xyz="0.0 -0.0 0.025" rpy="0 0 0"/>
    <geometry>
      <mesh filename="package://RotorAssemblyFullURDF_description/meshes/hub_1.stl" scale="0.001 0.001 0.001"/>
    </geometry>
    <material name="silver"/>
  </visual>
  <collision>
    <origin xyz="0.0 -0.0 0.025" rpy="0 0 0"/>
    <geometry>
      <mesh filename="package://RotorAssemblyFullURDF_description/meshes/hub_1.stl" scale="0.001 0.001 0.001"/>
    </geometry>
  </collision>
</link>

<link name="Teetering_Hub_1">
  <inertial>
    <origin xyz="-3.5419443219343136e-14 1.7881397990284334e-10 -9.317626531446521e-11" rpy="0 0 0"/>
    <mass value="0.00336023778370724"/>
    <inertia ixx="0.0" iyy="0.0" izz="0.0" ixy="0.0" iyz="0.0" ixz="0.0"/>
  </inertial>
  <visual>
    <origin xyz="-0.0 -0.0 -0.022" rpy="0 0 0"/>
    <geometry>
      <mesh filename="package://RotorAssemblyFullURDF_description/meshes/Teetering_Hub_1.stl" scale="0.001 0.001 0.001"/>
    </geometry>
    <material name="silver"/>
  </visual>
  <collision>
    <origin xyz="-0.0 -0.0 -0.022" rpy="0 0 0"/>
    <geometry>
      <mesh filename="package://RotorAssemblyFullURDF_description/meshes/Teetering_Hub_1.stl" scale="0.001 0.001 0.001"/>
    </geometry>
  </collision>
</link>

<link name="SideHubNegative_1">
  <inertial>
    <origin xyz="0.0008257992232984365 0.06000080025347367 0.0013887971279314439" rpy="0 0 0"/>
    <mass value="0.007461147444443305"/>
    <inertia ixx="2.1e-05" iyy="0.0" izz="2.1e-05" ixy="-0.0" iyz="0.0" ixz="0.0"/>
  </inertial>
  <visual>
    <origin xyz="-0.0 -0.016061 -0.020939" rpy="0 0 0"/>
    <geometry>
      <mesh filename="package://RotorAssemblyFullURDF_description/meshes/SideHubNegative_1.stl" scale="0.001 0.001 0.001"/>
    </geometry>
    <material name="silver"/>
  </visual>
  <collision>
    <origin xyz="-0.0 -0.016061 -0.020939" rpy="0 0 0"/>
    <geometry>
      <mesh filename="package://RotorAssemblyFullURDF_description/meshes/SideHubNegative_1.stl" scale="0.001 0.001 0.001"/>
    </geometry>
  </collision>
</link>

<link name="SideHubPositive_1">
  <inertial>
    <origin xyz="0.0008257992221561715 -0.06000079987073235 -0.001388797312438756" rpy="0 0 0"/>
    <mass value="0.0074611474493650465"/>
    <inertia ixx="2.1e-05" iyy="0.0" izz="2.1e-05" ixy="0.0" iyz="0.0" ixz="-0.0"/>
  </inertial>
  <visual>
    <origin xyz="-0.0 0.016061 -0.023061" rpy="0 0 0"/>
    <geometry>
      <mesh filename="package://RotorAssemblyFullURDF_description/meshes/SideHubPositive_1.stl" scale="0.001 0.001 0.001"/>
    </geometry>
    <material name="silver"/>
  </visual>
  <collision>
    <origin xyz="-0.0 0.016061 -0.023061" rpy="0 0 0"/>
    <geometry>
      <mesh filename="package://RotorAssemblyFullURDF_description/meshes/SideHubPositive_1.stl" scale="0.001 0.001 0.001"/>
    </geometry>
  </collision>
</link>

<joint name="Revolute 7" type="continuous">
  <origin xyz="0.0 0.0 -0.025" rpy="0 0 0"/>
  <parent link="base_link"/>
  <child link="hub_1"/>
  <axis xyz="-0.0 -0.0 -1.0"/>
</joint>

<joint name="Revolute 8" type="continuous">
  <origin xyz="0.0 0.0 0.047" rpy="0 0 0"/>
  <parent link="hub_1"/>
  <child link="Teetering_Hub_1"/>
  <axis xyz="1.0 -0.0 -0.0"/>
</joint>

<joint name="Revolute 9" type="continuous">
  <origin xyz="0.0 0.016061 -0.001061" rpy="0 0 0"/>
  <parent link="Teetering_Hub_1"/>
  <child link="SideHubNegative_1"/>
  <axis xyz="-0.0 0.707107 -0.707107"/>
</joint>

<joint name="Revolute 10" type="continuous">
  <origin xyz="0.0 -0.016061 0.001061" rpy="0 0 0"/>
  <parent link="Teetering_Hub_1"/>
  <child link="SideHubPositive_1"/>
  <axis xyz="-0.0 0.707107 -0.707107"/>
</joint>

</robot>
