<?xml version="1.0" ?>
<!-- =================================================================================== -->
<!-- |    This document was autogenerated by xacro from RotorAssemblyFullURDF.xacro    | -->
<!-- |    EDITING THIS FILE BY HAND IS NOT RECOMMENDED                                 | -->
<!-- =================================================================================== -->
<robot name="RotorAssemblyFullURDF">
  <material name="silver">
    <color rgba="0.40 0.40 0.40 1.000"/>
  </material>
  <material name="orange">
      <color rgba="1.0 0.423 0.039 1.0"/>
  </material>
  <material name="blue">
    <color rgba="0.0 0.0 0.8 1.0"/>
  </material>
  <material name="black">
    <color rgba="0.0 0.0 0.0 1.000"/>
  </material>
  <material name="red">
    <color rgba="0.900 0.05 0.05 1.000"/>
  </material>
  <transmission name="Revolute 7_tran">
    <type>transmission_interface/SimpleTransmission</type>
    <joint name="Revolute 7">
      <hardwareInterface>hardware_interface/EffortJointInterface</hardwareInterface>
    </joint>
    <actuator name="Revolute 7_actr">
      <hardwareInterface>hardware_interface/EffortJointInterface</hardwareInterface>
      <mechanicalReduction>1</mechanicalReduction>
    </actuator>
  </transmission>
  <transmission name="Revolute 8_tran">
    <type>transmission_interface/SimpleTransmission</type>
    <joint name="Revolute 8">
      <hardwareInterface>hardware_interface/EffortJointInterface</hardwareInterface>
    </joint>
    <actuator name="Revolute 8_actr">
      <hardwareInterface>hardware_interface/EffortJointInterface</hardwareInterface>
      <mechanicalReduction>1</mechanicalReduction>
    </actuator>
  </transmission>
  <transmission name="Revolute 9_tran">
    <type>transmission_interface/SimpleTransmission</type>
    <joint name="Revolute 9">
      <hardwareInterface>hardware_interface/EffortJointInterface</hardwareInterface>
    </joint>
    <actuator name="Revolute 9_actr">
      <hardwareInterface>hardware_interface/EffortJointInterface</hardwareInterface>
      <mechanicalReduction>1</mechanicalReduction>
    </actuator>
  </transmission>
  <transmission name="Revolute 10_tran">
    <type>transmission_interface/SimpleTransmission</type>
    <joint name="Revolute 10">
      <hardwareInterface>hardware_interface/EffortJointInterface</hardwareInterface>
    </joint>
    <actuator name="Revolute 10_actr">
      <hardwareInterface>hardware_interface/EffortJointInterface</hardwareInterface>
      <mechanicalReduction>1</mechanicalReduction>
    </actuator>
  </transmission>
  <gazebo>
    <plugin filename="libgazebo_ros_control.so" name="control"/>
  </gazebo>
  <gazebo reference="base_link">
    <material>Gazebo/Silver</material>
    <mu1>0.2</mu1>
    <mu2>0.2</mu2>
    <selfCollide>true</selfCollide>
    <gravity>true</gravity>
  </gazebo>
  <gazebo reference="hub_1">
    <material>Gazebo/Silver</material>
    <mu1>0.2</mu1>
    <mu2>0.2</mu2>
    <selfCollide>true</selfCollide>
  </gazebo>
  <gazebo reference="Teetering_Hub_1">
    <material>Gazebo/Orange</material>
    <mu1>0.2</mu1>
    <mu2>0.2</mu2>
    <selfCollide>true</selfCollide>
  </gazebo>
  <gazebo reference="SideHubNegative_1">
    <material>Gazebo/Silver</material>
    <mu1>0.2</mu1>
    <mu2>0.2</mu2>
    <selfCollide>true</selfCollide>
  </gazebo>
  <gazebo reference="SideHubPositive_1">
    <material>Gazebo/Silver</material>
    <mu1>0.2</mu1>
    <mu2>0.2</mu2>
    <selfCollide>true</selfCollide>
  </gazebo>
  <link name="base_link">
    <inertial>
      <origin rpy="0 0 0" xyz="7.738042425137721e-14 1.7881392864610074e-10 -0.013027047773476477"/>
      <mass value="0.04838658295139719"/>
      <inertia ixx="7e-06" ixy="0.0" ixz="0.0" iyy="7e-06" iyz="0.0" izz="1.3e-05"/>
    </inertial>
    <visual>
      <origin rpy="0 0 0" xyz="0 0 0"/>
      <geometry>
        <mesh filename="package://RotorAssemblyFullURDF_description/meshes/base_link.stl" scale="0.001 0.001 0.001"/>
      </geometry>
      <material name="red"/>
    </visual>
    <collision>
      <origin rpy="0 0 0" xyz="0 0 0"/>
      <geometry>
        <mesh filename="package://RotorAssemblyFullURDF_description/meshes/base_link.stl" scale="0.001 0.001 0.001"/>
      </geometry>
    </collision>
  </link>
  <link name="hub_1">
    <inertial>
      <origin rpy="0 0 0" xyz="5.134385663919432e-06 5.324199036162284e-08 0.02045097842795695"/>
      <mass value="0.025233763410004266"/>
      <inertia ixx="7e-06" ixy="-0.0" ixz="-0.0" iyy="8e-06" iyz="0.0" izz="1.1e-05"/>
    </inertial>
    <visual>
      <origin rpy="0 0 0" xyz="0.0 -0.0 0.025"/>
      <geometry>
        <mesh filename="package://RotorAssemblyFullURDF_description/meshes/hub_1.stl" scale="0.001 0.001 0.001"/>
      </geometry>
      <material name="black"/>
    </visual>
    <collision>
      <origin rpy="0 0 0" xyz="0.0 -0.0 0.025"/>
      <geometry>
        <mesh filename="package://RotorAssemblyFullURDF_description/meshes/hub_1.stl" scale="0.001 0.001 0.001"/>
      </geometry>
    </collision>
  </link>
  <link name="Teetering_Hub_1">
    <inertial>
      <origin rpy="0 0 0" xyz="-3.5419443219343136e-14 1.7881397990284334e-10 -9.317626531446521e-11"/>
      <mass value="0.00336023778370724"/>
      <inertia ixx="0.0" ixy="0.0" ixz="0.0" iyy="0.0" iyz="0.0" izz="0.0"/>
    </inertial>
    <visual>
      <origin rpy="0 0 0" xyz="-0.0 -0.0 -0.022"/>
      <geometry>
        <mesh filename="package://RotorAssemblyFullURDF_description/meshes/Teetering_Hub_1.stl" scale="0.001 0.001 0.001"/>
      </geometry>
      <material name="orange"/>
    </visual>
    <collision>
      <origin rpy="0 0 0" xyz="-0.0 -0.0 -0.022"/>
      <geometry>
        <mesh filename="package://RotorAssemblyFullURDF_description/meshes/Teetering_Hub_1.stl" scale="0.001 0.001 0.001"/>
      </geometry>
    </collision>
  </link>
  <link name="SideHubNegative_1">
    <inertial>
      <origin rpy="0 0 0" xyz="0.0008257992232984365 0.06000080025347367 0.0013887971279314439"/>
      <mass value="0.007461147444443305"/>
      <inertia ixx="2.1e-05" ixy="-0.0" ixz="0.0" iyy="0.0" iyz="0.0" izz="2.1e-05"/>
    </inertial>
    <visual>
      <origin rpy="0 0 0" xyz="-0.0 -0.016061 -0.020939"/>
      <geometry>
        <mesh filename="package://RotorAssemblyFullURDF_description/meshes/SideHubNegative_1.stl" scale="0.001 0.001 0.001"/>
      </geometry>
      <material name="silver"/>
    </visual>
    <collision>
      <origin rpy="0 0 0" xyz="-0.0 -0.016061 -0.020939"/>
      <geometry>
        <mesh filename="package://RotorAssemblyFullURDF_description/meshes/SideHubNegative_1.stl" scale="0.001 0.001 0.001"/>
      </geometry>
    </collision>
  </link>
  <link name="SideHubPositive_1">
    <inertial>
      <origin rpy="0 0 0" xyz="0.0008257992221561715 -0.06000079987073235 -0.001388797312438756"/>
      <mass value="0.0074611474493650465"/>
      <inertia ixx="2.1e-05" ixy="0.0" ixz="-0.0" iyy="0.0" iyz="0.0" izz="2.1e-05"/>
    </inertial>
    <visual>
      <origin rpy="0 0 0" xyz="-0.0 0.016061 -0.023061"/>
      <geometry>
        <mesh filename="package://RotorAssemblyFullURDF_description/meshes/SideHubPositive_1.stl" scale="0.001 0.001 0.001"/>
      </geometry>
      <material name="silver"/>
    </visual>
    <collision>
      <origin rpy="0 0 0" xyz="-0.0 0.016061 -0.023061"/>
      <geometry>
        <mesh filename="package://RotorAssemblyFullURDF_description/meshes/SideHubPositive_1.stl" scale="0.001 0.001 0.001"/>
      </geometry>
    </collision>
  </link>
  <joint name="Revolute 7" type="continuous">
    <origin rpy="0 0 0" xyz="0.0 0.0 -0.025"/>
    <parent link="base_link"/>
    <child link="hub_1"/>
    <axis xyz="-0.0 -0.0 -1.0"/>
  </joint>
  <joint name="Revolute 8" type="continuous">
    <origin rpy="0 0 0" xyz="0.0 0.0 0.047"/>
    <parent link="hub_1"/>
    <child link="Teetering_Hub_1"/>
    <axis xyz="1.0 -0.0 -0.0"/>
  </joint>
  <joint name="Revolute 9" type="continuous">
    <origin rpy="0 0 0" xyz="0.0 0.016061 -0.001061"/>
    <parent link="Teetering_Hub_1"/>
    <child link="SideHubNegative_1"/>
    <axis xyz="-0.0 0.707107 -0.707107"/>
  </joint>
  <joint name="Revolute 10" type="continuous">
    <origin rpy="0 0 0" xyz="0.0 -0.016061 0.001061"/>
    <parent link="Teetering_Hub_1"/>
    <child link="SideHubPositive_1"/>
    <axis xyz="-0.0 0.707107 -0.707107"/>
  </joint>
</robot>

